Workbook

Sheet Start
B1: Plannerij
B2: Budgetplanner
B3: Grip op je geld – maand voor maand. Werkt in Excel, Google Sheets en Numbers.
B5: Zo gebruik je dit bestand
B6: 1. | C6: Ga naar het tabblad Instellingen. Vul de naam van je huishouden en je startmaand in en pas de categorienamen aan naar jouw situatie. Alle maandtabbladen nemen die namen automatisch over.
B7: 2. | C7: Open het tabblad van de huidige maand (Januari t/m December) en vul in de kolom Begroot in wat je verwacht aan inkomen, vaste lasten, variabele uitgaven en sparen.
B8: 3. | C8: Vul in de loop van de maand je werkelijke inkomen en vaste lasten in (groene cellen in de kolom Werkelijk).
B9: 4. | C9: Noteer variabele uitgaven (boodschappen, uit eten, kleding, …) in het Uitgavenlogboek rechts op het maandblad: datum, omschrijving, categorie (keuzelijst) en bedrag. De kolom Werkelijk bij Variabele uitgaven telt dit automatisch op per categorie (SUMIF).
B10: 5. | C10: Vul onder Sparen in wat je werkelijk naar elk spaardoel hebt overgemaakt. Het tabblad Spaardoelen houdt de voortgang bij.
B11: 6. | C11: Bekijk het samenvattingskader rechtsboven op het maandblad: Totaal inkomen, Totaal uitgaven, Gespaard en Over/tekort. Rood betekent dat je meer hebt uitgegeven dan er binnenkwam.
B12: 7. | C12: Kijk regelmatig op het Jaaroverzicht voor het totaalbeeld: inkomen versus uitgaven per maand, je spaarquote en de grafiek.
B13: 8. | C13: Gebruik de extra tabbladen Schulden, Abonnementen en Spaarpotjes 52 weken om schulden af te bouwen, abonnementen op te ruimen en spelenderwijs te sparen.
B15: Legenda
C16: Groene cel = invulcel. Hier vul je je eigen cijfers in.
C17: Witte cel = formule. Niet aanpassen; deze rekent automatisch.
C18: Zandkleurige cel = subtotaal of samenvatting.
C19: Voorbeeld-bedragen? Vul je eigen cijfers in in de groene cellen. Het bestand is bewust leeg opgeleverd, zodat je met een schone lei begint.
B21: Tips
B22: • | C22: Verschil-kolom: bij Inkomen is dat Werkelijk – Begroot (positief = meer binnen dan verwacht). Bij uitgaven is het Begroot – Werkelijk (positief = binnen budget gebleven, rood = overschreden).
B23: • | C23: Categorie hernoemen? Doe dat alléén op het tabblad Instellingen; alle maanden en keuzelijsten volgen automatisch.
B24: • | C24: Spaarquote = Gespaard ÷ Inkomen. Een spaarquote van 10–20% is een mooi streven; alles boven 0% is winst.
B25: • | C25: Bouw eerst een noodbuffer van 3 maanden vaste lasten op vóór je aan grotere spaardoelen begint.
B26: • | C26: Vul het logboek wekelijks in (bijvoorbeeld op zondagavond) – dat kost 5 minuten en houdt je overzicht actueel.
B27: • | C27: Wil je een tabblad beschermen tegen per ongeluk overschrijven? Gebruik 'Blad beveiligen' in Excel of Google Sheets; de groene cellen blijven dan invulbaar als je ze eerst ontgrendelt.
B28: • | C28: Google Sheets: upload het bestand via Bestand > Importeren. Numbers: openen werkt direct; formules blijven behouden.
C30: Werkt in Excel, Google Sheets en Numbers. · © Plannerij

Sheet Instellingen
B1: Plannerij
B2: Instellingen
B3: Vul de groene cellen in. Categorienamen die je hier wijzigt, worden overal overgenomen.
B5: Naam huishouden
B6: Startmaand (datum, bv. 01-01-2027)
B7: Jaar | C7: =IF(C6="","",YEAR(C6))
B8: Inkomen | D8: Vaste lasten | F8: Variabele uitgaven | H8: Spaardoelen
B9: Salaris | D9: Huur/Hypotheek | F9: Boodschappen | H9: Noodbuffer
B10: Toeslagen | D10: Energie | F10: Uit eten | H10: Vakantie
B11: Freelance | D11: Water | F11: Kleding | H11: Grote aankoop
B12: Overig | D12: Zorgverzekering | F12: Persoonlijke verzorging | H12: Pensioen/beleggen
D13: Overige verzekeringen | F13: Vervoer/Brandstof
D14: Internet & TV | F14: Cadeaus
D15: Telefoon | F15: Vrije tijd
D16: Abonnementen | F16: Vakantie
D17: Gemeentelijke belastingen | F17: Huis & Tuin
D18: Auto/OV | F18: Gezondheid
D19: Kinderopvang | F19: Overig
D20: Aflossing schulden
B23: Tip: hernoem categorieën gerust, maar laat de volgorde en het aantal rijen staan. De keuzelijst in het Uitgavenlogboek gebruikt de lijst 'Variabele uitgaven'.

Sheet Jaaroverzicht
B1: Plannerij
B2: Jaaroverzicht
B3: Werkelijke cijfers uit de twaalf maandtabbladen. Alles rekent automatisch. | D3: =IF(Instellingen!$C$5="","",Instellingen!$C$5)
B5: Totaal inkomen | D5: Totaal uitgaven | F5: Totaal gespaard | H5: Gemiddelde spaarquote
B6: =C21 | D6: =G21 | F6: =F21 | H6: =I22
B8: Maand | C8: Inkomen | D8: Vaste lasten | E8: Variabele uitgaven | F8: Sparen | G8: Totaal uitgaven | H8: Resultaat | I8: Spaarquote
B9: Januari | C9: ='Januari'!D9 | D9: ='Januari'!D24 | E9: ='Januari'!D38 | F9: ='Januari'!D45 | G9: =D9+E9 | H9: =C9-G9-F9 | I9: =IFERROR(F9/C9,0)
B10: Februari | C10: ='Februari'!D9 | D10: ='Februari'!D24 | E10: ='Februari'!D38 | F10: ='Februari'!D45 | G10: =D10+E10 | H10: =C10-G10-F10 | I10: =IFERROR(F10/C10,0)
B11: Maart | C11: ='Maart'!D9 | D11: ='Maart'!D24 | E11: ='Maart'!D38 | F11: ='Maart'!D45 | G11: =D11+E11 | H11: =C11-G11-F11 | I11: =IFERROR(F11/C11,0)
B12: April | C12: ='April'!D9 | D12: ='April'!D24 | E12: ='April'!D38 | F12: ='April'!D45 | G12: =D12+E12 | H12: =C12-G12-F12 | I12: =IFERROR(F12/C12,0)
B13: Mei | C13: ='Mei'!D9 | D13: ='Mei'!D24 | E13: ='Mei'!D38 | F13: ='Mei'!D45 | G13: =D13+E13 | H13: =C13-G13-F13 | I13: =IFERROR(F13/C13,0)
B14: Juni | C14: ='Juni'!D9 | D14: ='Juni'!D24 | E14: ='Juni'!D38 | F14: ='Juni'!D45 | G14: =D14+E14 | H14: =C14-G14-F14 | I14: =IFERROR(F14/C14,0)
B15: Juli | C15: ='Juli'!D9 | D15: ='Juli'!D24 | E15: ='Juli'!D38 | F15: ='Juli'!D45 | G15: =D15+E15 | H15: =C15-G15-F15 | I15: =IFERROR(F15/C15,0)
B16: Augustus | C16: ='Augustus'!D9 | D16: ='Augustus'!D24 | E16: ='Augustus'!D38 | F16: ='Augustus'!D45 | G16: =D16+E16 | H16: =C16-G16-F16 | I16: =IFERROR(F16/C16,0)
B17: September | C17: ='September'!D9 | D17: ='September'!D24 | E17: ='September'!D38 | F17: ='September'!D45 | G17: =D17+E17 | H17: =C17-G17-F17 | I17: =IFERROR(F17/C17,0)
B18: Oktober | C18: ='Oktober'!D9 | D18: ='Oktober'!D24 | E18: ='Oktober'!D38 | F18: ='Oktober'!D45 | G18: =D18+E18 | H18: =C18-G18-F18 | I18: =IFERROR(F18/C18,0)
B19: November | C19: ='November'!D9 | D19: ='November'!D24 | E19: ='November'!D38 | F19: ='November'!D45 | G19: =D19+E19 | H19: =C19-G19-F19 | I19: =IFERROR(F19/C19,0)
B20: December | C20: ='December'!D9 | D20: ='December'!D24 | E20: ='December'!D38 | F20: ='December'!D45 | G20: =D20+E20 | H20: =C20-G20-F20 | I20: =IFERROR(F20/C20,0)
B21: Totaal | C21: =SUM(C9:C20) | D21: =SUM(D9:D20) | E21: =SUM(E9:E20) | F21: =SUM(F9:F20) | G21: =SUM(G9:G20) | H21: =SUM(H9:H20) | I21: =IFERROR(F21/C21,0)
B22: Gemiddelde | C22: =AVERAGE(C9:C20) | D22: =AVERAGE(D9:D20) | E22: =AVERAGE(E9:E20) | F22: =AVERAGE(F9:F20) | G22: =AVERAGE(G9:G20) | H22: =AVERAGE(H9:H20) | I22: =IFERROR(F21/C21,0)
B23: Resultaat = Inkomen – Totaal uitgaven – Sparen. Spaarquote = Sparen ÷ Inkomen.

Sheet Januari
B1: Plannerij
B2: Januari
B3: =IF(Instellingen!$C$5="","",Instellingen!$C$5)
B4: A · Inkomen | C4: Begroot | D4: Werkelijk | E4: Verschil | G4: Samenvatting | I4: Begroot | J4: Werkelijk
B5: =Instellingen!$B$9 | E5: =D5-C5 | G5: Totaal inkomen | I5: =C9 | J5: =D9
B6: =Instellingen!$B$10 | E6: =D6-C6 | G6: Totaal uitgaven | I6: =C24+C38 | J6: =D24+D38
B7: =Instellingen!$B$11 | E7: =D7-C7 | G7: Gespaard | I7: =C45 | J7: =D45
B8: =Instellingen!$B$12 | E8: =D8-C8 | G8: Over / tekort | I8: =I5-I6-I7 | J8: =J5-J6-J7
B9: Subtotaal | C9: =SUM(C5:C8) | D9: =SUM(D5:D8) | E9: =SUM(E5:E8)
G10: Uitgavenlogboek | I10: Kies een categorie uit de lijst; het bedrag telt automatisch op bij Variabele uitgaven.
B11: B · Vaste lasten | C11: Begroot | D11: Werkelijk | E11: Verschil | G11: Datum | H11: Omschrijving | I11: Categorie | J11: Bedrag
B12: =Instellingen!$D$9 | E12: =C12-D12
B13: =Instellingen!$D$10 | E13: =C13-D13
B14: =Instellingen!$D$11 | E14: =C14-D14
B15: =Instellingen!$D$12 | E15: =C15-D15
B16: =Instellingen!$D$13 | E16: =C16-D16
B17: =Instellingen!$D$14 | E17: =C17-D17
B18: =Instellingen!$D$15 | E18: =C18-D18
B19: =Instellingen!$D$16 | E19: =C19-D19
B20: =Instellingen!$D$17 | E20: =C20-D20
B21: =Instellingen!$D$18 | E21: =C21-D21
B22: =Instellingen!$D$19 | E22: =C22-D22
B23: =Instellingen!$D$20 | E23: =C23-D23
B24: Subtotaal | C24: =SUM(C12:C23) | D24: =SUM(D12:D23) | E24: =SUM(E12:E23)
B26: C · Variabele uitgaven | C26: Begroot | D26: Werkelijk | E26: Verschil
B27: =Instellingen!$F$9 | D27: =SUMIF($I$12:$I$51,B27,$J$12:$J$51) | E27: =C27-D27
B28: =Instellingen!$F$10 | D28: =SUMIF($I$12:$I$51,B28,$J$12:$J$51) | E28: =C28-D28
B29: =Instellingen!$F$11 | D29: =SUMIF($I$12:$I$51,B29,$J$12:$J$51) | E29: =C29-D29
B30: =Instellingen!$F$12 | D30: =SUMIF($I$12:$I$51,B30,$J$12:$J$51) | E30: =C30-D30
B31: =Instellingen!$F$13 | D31: =SUMIF($I$12:$I$51,B31,$J$12:$J$51) | E31: =C31-D31
B32: =Instellingen!$F$14 | D32: =SUMIF($I$12:$I$51,B32,$J$12:$J$51) | E32: =C32-D32
B33: =Instellingen!$F$15 | D33: =SUMIF($I$12:$I$51,B33,$J$12:$J$51) | E33: =C33-D33
B34: =Instellingen!$F$16 | D34: =SUMIF($I$12:$I$51,B34,$J$12:$J$51) | E34: =C34-D34
B35: =Instellingen!$F$17 | D35: =SUMIF($I$12:$I$51,B35,$J$12:$J$51) | E35: =C35-D35
B36: =Instellingen!$F$18 | D36: =SUMIF($I$12:$I$51,B36,$J$12:$J$51) | E36: =C36-D36
B37: =Instellingen!$F$19 | D37: =SUMIF($I$12:$I$51,B37,$J$12:$J$51) | E37: =C37-D37
B38: Subtotaal | C38: =SUM(C27:C37) | D38: =SUM(D27:D37) | E38: =SUM(E27:E37)
B40: D · Sparen | C40: Begroot | D40: Werkelijk | E40: Verschil
B41: =Instellingen!$H$9 | E41: =D41-C41
B42: =Instellingen!$H$10 | E42: =D42-C42
...

Sheet Februari
B1: Plannerij
B2: Februari
B3: =IF(Instellingen!$C$5="","",Instellingen!$C$5)
B4: A · Inkomen | C4: Begroot | D4: Werkelijk | E4: Verschil | G4: Samenvatting | I4: Begroot | J4: Werkelijk
B5: =Instellingen!$B$9 | E5: =D5-C5 | G5: Totaal inkomen | I5: =C9 | J5: =D9
B6: =Instellingen!$B$10 | E6: =D6-C6 | G6: Totaal uitgaven | I6: =C24+C38 | J6: =D24+D38
B7: =Instellingen!$B$11 | E7: =D7-C7 | G7: Gespaard | I7: =C45 | J7: =D45
B8: =Instellingen!$B$12 | E8: =D8-C8 | G8: Over / tekort | I8: =I5-I6-I7 | J8: =J5-J6-J7
B9: Subtotaal | C9: =SUM(C5:C8) | D9: =SUM(D5:D8) | E9: =SUM(E5:E8)
G10: Uitgavenlogboek | I10: Kies een categorie uit de lijst; het bedrag telt automatisch op bij Variabele uitgaven.
B11: B · Vaste lasten | C11: Begroot | D11: Werkelijk | E11: Verschil | G11: Datum | H11: Omschrijving | I11: Categorie | J11: Bedrag
B12: =Instellingen!$D$9 | E12: =C12-D12
B13: =Instellingen!$D$10 | E13: =C13-D13
B14: =Instellingen!$D$11 | E14: =C14-D14
B15: =Instellingen!$D$12 | E15: =C15-D15
B16: =Instellingen!$D$13 | E16: =C16-D16
B17: =Instellingen!$D$14 | E17: =C17-D17
B18: =Instellingen!$D$15 | E18: =C18-D18
B19: =Instellingen!$D$16 | E19: =C19-D19
B20: =Instellingen!$D$17 | E20: =C20-D20
B21: =Instellingen!$D$18 | E21: =C21-D21
B22: =Instellingen!$D$19 | E22: =C22-D22
B23: =Instellingen!$D$20 | E23: =C23-D23
B24: Subtotaal | C24: =SUM(C12:C23) | D24: =SUM(D12:D23) | E24: =SUM(E12:E23)
B26: C · Variabele uitgaven | C26: Begroot | D26: Werkelijk | E26: Verschil
B27: =Instellingen!$F$9 | D27: =SUMIF($I$12:$I$51,B27,$J$12:$J$51) | E27: =C27-D27
B28: =Instellingen!$F$10 | D28: =SUMIF($I$12:$I$51,B28,$J$12:$J$51) | E28: =C28-D28
B29: =Instellingen!$F$11 | D29: =SUMIF($I$12:$I$51,B29,$J$12:$J$51) | E29: =C29-D29
B30: =Instellingen!$F$12 | D30: =SUMIF($I$12:$I$51,B30,$J$12:$J$51) | E30: =C30-D30
B31: =Instellingen!$F$13 | D31: =SUMIF($I$12:$I$51,B31,$J$12:$J$51) | E31: =C31-D31
B32: =Instellingen!$F$14 | D32: =SUMIF($I$12:$I$51,B32,$J$12:$J$51) | E32: =C32-D32
B33: =Instellingen!$F$15 | D33: =SUMIF($I$12:$I$51,B33,$J$12:$J$51) | E33: =C33-D33
B34: =Instellingen!$F$16 | D34: =SUMIF($I$12:$I$51,B34,$J$12:$J$51) | E34: =C34-D34
B35: =Instellingen!$F$17 | D35: =SUMIF($I$12:$I$51,B35,$J$12:$J$51) | E35: =C35-D35
B36: =Instellingen!$F$18 | D36: =SUMIF($I$12:$I$51,B36,$J$12:$J$51) | E36: =C36-D36
B37: =Instellingen!$F$19 | D37: =SUMIF($I$12:$I$51,B37,$J$12:$J$51) | E37: =C37-D37
B38: Subtotaal | C38: =SUM(C27:C37) | D38: =SUM(D27:D37) | E38: =SUM(E27:E37)
B40: D · Sparen | C40: Begroot | D40: Werkelijk | E40: Verschil
B41: =Instellingen!$H$9 | E41: =D41-C41
B42: =Instellingen!$H$10 | E42: =D42-C42
...

Sheet Maart
B1: Plannerij
B2: Maart
B3: =IF(Instellingen!$C$5="","",Instellingen!$C$5)
B4: A · Inkomen | C4: Begroot | D4: Werkelijk | E4: Verschil | G4: Samenvatting | I4: Begroot | J4: Werkelijk
B5: =Instellingen!$B$9 | E5: =D5-C5 | G5: Totaal inkomen | I5: =C9 | J5: =D9
B6: =Instellingen!$B$10 | E6: =D6-C6 | G6: Totaal uitgaven | I6: =C24+C38 | J6: =D24+D38
B7: =Instellingen!$B$11 | E7: =D7-C7 | G7: Gespaard | I7: =C45 | J7: =D45
B8: =Instellingen!$B$12 | E8: =D8-C8 | G8: Over / tekort | I8: =I5-I6-I7 | J8: =J5-J6-J7
B9: Subtotaal | C9: =SUM(C5:C8) | D9: =SUM(D5:D8) | E9: =SUM(E5:E8)
G10: Uitgavenlogboek | I10: Kies een categorie uit de lijst; het bedrag telt automatisch op bij Variabele uitgaven.
B11: B · Vaste lasten | C11: Begroot | D11: Werkelijk | E11: Verschil | G11: Datum | H11: Omschrijving | I11: Categorie | J11: Bedrag
B12: =Instellingen!$D$9 | E12: =C12-D12
B13: =Instellingen!$D$10 | E13: =C13-D13
B14: =Instellingen!$D$11 | E14: =C14-D14
B15: =Instellingen!$D$12 | E15: =C15-D15
B16: =Instellingen!$D$13 | E16: =C16-D16
B17: =Instellingen!$D$14 | E17: =C17-D17
B18: =Instellingen!$D$15 | E18: =C18-D18
B19: =Instellingen!$D$16 | E19: =C19-D19
B20: =Instellingen!$D$17 | E20: =C20-D20
B21: =Instellingen!$D$18 | E21: =C21-D21
B22: =Instellingen!$D$19 | E22: =C22-D22
B23: =Instellingen!$D$20 | E23: =C23-D23
B24: Subtotaal | C24: =SUM(C12:C23) | D24: =SUM(D12:D23) | E24: =SUM(E12:E23)
B26: C · Variabele uitgaven | C26: Begroot | D26: Werkelijk | E26: Verschil
B27: =Instellingen!$F$9 | D27: =SUMIF($I$12:$I$51,B27,$J$12:$J$51) | E27: =C27-D27
B28: =Instellingen!$F$10 | D28: =SUMIF($I$12:$I$51,B28,$J$12:$J$51) | E28: =C28-D28
B29: =Instellingen!$F$11 | D29: =SUMIF($I$12:$I$51,B29,$J$12:$J$51) | E29: =C29-D29
B30: =Instellingen!$F$12 | D30: =SUMIF($I$12:$I$51,B30,$J$12:$J$51) | E30: =C30-D30
B31: =Instellingen!$F$13 | D31: =SUMIF($I$12:$I$51,B31,$J$12:$J$51) | E31: =C31-D31
B32: =Instellingen!$F$14 | D32: =SUMIF($I$12:$I$51,B32,$J$12:$J$51) | E32: =C32-D32
B33: =Instellingen!$F$15 | D33: =SUMIF($I$12:$I$51,B33,$J$12:$J$51) | E33: =C33-D33
B34: =Instellingen!$F$16 | D34: =SUMIF($I$12:$I$51,B34,$J$12:$J$51) | E34: =C34-D34
B35: =Instellingen!$F$17 | D35: =SUMIF($I$12:$I$51,B35,$J$12:$J$51) | E35: =C35-D35
B36: =Instellingen!$F$18 | D36: =SUMIF($I$12:$I$51,B36,$J$12:$J$51) | E36: =C36-D36
B37: =Instellingen!$F$19 | D37: =SUMIF($I$12:$I$51,B37,$J$12:$J$51) | E37: =C37-D37
B38: Subtotaal | C38: =SUM(C27:C37) | D38: =SUM(D27:D37) | E38: =SUM(E27:E37)
B40: D · Sparen | C40: Begroot | D40: Werkelijk | E40: Verschil
B41: =Instellingen!$H$9 | E41: =D41-C41
B42: =Instellingen!$H$10 | E42: =D42-C42
...

Sheet April
B1: Plannerij
B2: April
B3: =IF(Instellingen!$C$5="","",Instellingen!$C$5)
B4: A · Inkomen | C4: Begroot | D4: Werkelijk | E4: Verschil | G4: Samenvatting | I4: Begroot | J4: Werkelijk
B5: =Instellingen!$B$9 | E5: =D5-C5 | G5: Totaal inkomen | I5: =C9 | J5: =D9
B6: =Instellingen!$B$10 | E6: =D6-C6 | G6: Totaal uitgaven | I6: =C24+C38 | J6: =D24+D38
B7: =Instellingen!$B$11 | E7: =D7-C7 | G7: Gespaard | I7: =C45 | J7: =D45
B8: =Instellingen!$B$12 | E8: =D8-C8 | G8: Over / tekort | I8: =I5-I6-I7 | J8: =J5-J6-J7
B9: Subtotaal | C9: =SUM(C5:C8) | D9: =SUM(D5:D8) | E9: =SUM(E5:E8)
G10: Uitgavenlogboek | I10: Kies een categorie uit de lijst; het bedrag telt automatisch op bij Variabele uitgaven.
B11: B · Vaste lasten | C11: Begroot | D11: Werkelijk | E11: Verschil | G11: Datum | H11: Omschrijving | I11: Categorie | J11: Bedrag
B12: =Instellingen!$D$9 | E12: =C12-D12
B13: =Instellingen!$D$10 | E13: =C13-D13
B14: =Instellingen!$D$11 | E14: =C14-D14
B15: =Instellingen!$D$12 | E15: =C15-D15
B16: =Instellingen!$D$13 | E16: =C16-D16
B17: =Instellingen!$D$14 | E17: =C17-D17
B18: =Instellingen!$D$15 | E18: =C18-D18
B19: =Instellingen!$D$16 | E19: =C19-D19
B20: =Instellingen!$D$17 | E20: =C20-D20
B21: =Instellingen!$D$18 | E21: =C21-D21
B22: =Instellingen!$D$19 | E22: =C22-D22
B23: =Instellingen!$D$20 | E23: =C23-D23
B24: Subtotaal | C24: =SUM(C12:C23) | D24: =SUM(D12:D23) | E24: =SUM(E12:E23)
B26: C · Variabele uitgaven | C26: Begroot | D26: Werkelijk | E26: Verschil
B27: =Instellingen!$F$9 | D27: =SUMIF($I$12:$I$51,B27,$J$12:$J$51) | E27: =C27-D27
B28: =Instellingen!$F$10 | D28: =SUMIF($I$12:$I$51,B28,$J$12:$J$51) | E28: =C28-D28
B29: =Instellingen!$F$11 | D29: =SUMIF($I$12:$I$51,B29,$J$12:$J$51) | E29: =C29-D29
B30: =Instellingen!$F$12 | D30: =SUMIF($I$12:$I$51,B30,$J$12:$J$51) | E30: =C30-D30
B31: =Instellingen!$F$13 | D31: =SUMIF($I$12:$I$51,B31,$J$12:$J$51) | E31: =C31-D31
B32: =Instellingen!$F$14 | D32: =SUMIF($I$12:$I$51,B32,$J$12:$J$51) | E32: =C32-D32
B33: =Instellingen!$F$15 | D33: =SUMIF($I$12:$I$51,B33,$J$12:$J$51) | E33: =C33-D33
B34: =Instellingen!$F$16 | D34: =SUMIF($I$12:$I$51,B34,$J$12:$J$51) | E34: =C34-D34
B35: =Instellingen!$F$17 | D35: =SUMIF($I$12:$I$51,B35,$J$12:$J$51) | E35: =C35-D35
B36: =Instellingen!$F$18 | D36: =SUMIF($I$12:$I$51,B36,$J$12:$J$51) | E36: =C36-D36
B37: =Instellingen!$F$19 | D37: =SUMIF($I$12:$I$51,B37,$J$12:$J$51) | E37: =C37-D37
B38: Subtotaal | C38: =SUM(C27:C37) | D38: =SUM(D27:D37) | E38: =SUM(E27:E37)
B40: D · Sparen | C40: Begroot | D40: Werkelijk | E40: Verschil
B41: =Instellingen!$H$9 | E41: =D41-C41
B42: =Instellingen!$H$10 | E42: =D42-C42
...

Sheet Mei
B1: Plannerij
B2: Mei
B3: =IF(Instellingen!$C$5="","",Instellingen!$C$5)
B4: A · Inkomen | C4: Begroot | D4: Werkelijk | E4: Verschil | G4: Samenvatting | I4: Begroot | J4: Werkelijk
B5: =Instellingen!$B$9 | E5: =D5-C5 | G5: Totaal inkomen | I5: =C9 | J5: =D9
B6: =Instellingen!$B$10 | E6: =D6-C6 | G6: Totaal uitgaven | I6: =C24+C38 | J6: =D24+D38
B7: =Instellingen!$B$11 | E7: =D7-C7 | G7: Gespaard | I7: =C45 | J7: =D45
B8: =Instellingen!$B$12 | E8: =D8-C8 | G8: Over / tekort | I8: =I5-I6-I7 | J8: =J5-J6-J7
B9: Subtotaal | C9: =SUM(C5:C8) | D9: =SUM(D5:D8) | E9: =SUM(E5:E8)
G10: Uitgavenlogboek | I10: Kies een categorie uit de lijst; het bedrag telt automatisch op bij Variabele uitgaven.
B11: B · Vaste lasten | C11: Begroot | D11: Werkelijk | E11: Verschil | G11: Datum | H11: Omschrijving | I11: Categorie | J11: Bedrag
B12: =Instellingen!$D$9 | E12: =C12-D12
B13: =Instellingen!$D$10 | E13: =C13-D13
B14: =Instellingen!$D$11 | E14: =C14-D14
B15: =Instellingen!$D$12 | E15: =C15-D15
B16: =Instellingen!$D$13 | E16: =C16-D16
B17: =Instellingen!$D$14 | E17: =C17-D17
B18: =Instellingen!$D$15 | E18: =C18-D18
B19: =Instellingen!$D$16 | E19: =C19-D19
B20: =Instellingen!$D$17 | E20: =C20-D20
B21: =Instellingen!$D$18 | E21: =C21-D21
B22: =Instellingen!$D$19 | E22: =C22-D22
B23: =Instellingen!$D$20 | E23: =C23-D23
B24: Subtotaal | C24: =SUM(C12:C23) | D24: =SUM(D12:D23) | E24: =SUM(E12:E23)
B26: C · Variabele uitgaven | C26: Begroot | D26: Werkelijk | E26: Verschil
B27: =Instellingen!$F$9 | D27: =SUMIF($I$12:$I$51,B27,$J$12:$J$51) | E27: =C27-D27
B28: =Instellingen!$F$10 | D28: =SUMIF($I$12:$I$51,B28,$J$12:$J$51) | E28: =C28-D28
B29: =Instellingen!$F$11 | D29: =SUMIF($I$12:$I$51,B29,$J$12:$J$51) | E29: =C29-D29
B30: =Instellingen!$F$12 | D30: =SUMIF($I$12:$I$51,B30,$J$12:$J$51) | E30: =C30-D30
B31: =Instellingen!$F$13 | D31: =SUMIF($I$12:$I$51,B31,$J$12:$J$51) | E31: =C31-D31
B32: =Instellingen!$F$14 | D32: =SUMIF($I$12:$I$51,B32,$J$12:$J$51) | E32: =C32-D32
B33: =Instellingen!$F$15 | D33: =SUMIF($I$12:$I$51,B33,$J$12:$J$51) | E33: =C33-D33
B34: =Instellingen!$F$16 | D34: =SUMIF($I$12:$I$51,B34,$J$12:$J$51) | E34: =C34-D34
B35: =Instellingen!$F$17 | D35: =SUMIF($I$12:$I$51,B35,$J$12:$J$51) | E35: =C35-D35
B36: =Instellingen!$F$18 | D36: =SUMIF($I$12:$I$51,B36,$J$12:$J$51) | E36: =C36-D36
B37: =Instellingen!$F$19 | D37: =SUMIF($I$12:$I$51,B37,$J$12:$J$51) | E37: =C37-D37
B38: Subtotaal | C38: =SUM(C27:C37) | D38: =SUM(D27:D37) | E38: =SUM(E27:E37)
B40: D · Sparen | C40: Begroot | D40: Werkelijk | E40: Verschil
B41: =Instellingen!$H$9 | E41: =D41-C41
B42: =Instellingen!$H$10 | E42: =D42-C42
...

Sheet Juni
B1: Plannerij
B2: Juni
B3: =IF(Instellingen!$C$5="","",Instellingen!$C$5)
B4: A · Inkomen | C4: Begroot | D4: Werkelijk | E4: Verschil | G4: Samenvatting | I4: Begroot | J4: Werkelijk
B5: =Instellingen!$B$9 | E5: =D5-C5 | G5: Totaal inkomen | I5: =C9 | J5: =D9
B6: =Instellingen!$B$10 | E6: =D6-C6 | G6: Totaal uitgaven | I6: =C24+C38 | J6: =D24+D38
B7: =Instellingen!$B$11 | E7: =D7-C7 | G7: Gespaard | I7: =C45 | J7: =D45
B8: =Instellingen!$B$12 | E8: =D8-C8 | G8: Over / tekort | I8: =I5-I6-I7 | J8: =J5-J6-J7
B9: Subtotaal | C9: =SUM(C5:C8) | D9: =SUM(D5:D8) | E9: =SUM(E5:E8)
G10: Uitgavenlogboek | I10: Kies een categorie uit de lijst; het bedrag telt automatisch op bij Variabele uitgaven.
B11: B · Vaste lasten | C11: Begroot | D11: Werkelijk | E11: Verschil | G11: Datum | H11: Omschrijving | I11: Categorie | J11: Bedrag
B12: =Instellingen!$D$9 | E12: =C12-D12
B13: =Instellingen!$D$10 | E13: =C13-D13
B14: =Instellingen!$D$11 | E14: =C14-D14
B15: =Instellingen!$D$12 | E15: =C15-D15
B16: =Instellingen!$D$13 | E16: =C16-D16
B17: =Instellingen!$D$14 | E17: =C17-D17
B18: =Instellingen!$D$15 | E18: =C18-D18
B19: =Instellingen!$D$16 | E19: =C19-D19
B20: =Instellingen!$D$17 | E20: =C20-D20
B21: =Instellingen!$D$18 | E21: =C21-D21
B22: =Instellingen!$D$19 | E22: =C22-D22
B23: =Instellingen!$D$20 | E23: =C23-D23
B24: Subtotaal | C24: =SUM(C12:C23) | D24: =SUM(D12:D23) | E24: =SUM(E12:E23)
B26: C · Variabele uitgaven | C26: Begroot | D26: Werkelijk | E26: Verschil
B27: =Instellingen!$F$9 | D27: =SUMIF($I$12:$I$51,B27,$J$12:$J$51) | E27: =C27-D27
B28: =Instellingen!$F$10 | D28: =SUMIF($I$12:$I$51,B28,$J$12:$J$51) | E28: =C28-D28
B29: =Instellingen!$F$11 | D29: =SUMIF($I$12:$I$51,B29,$J$12:$J$51) | E29: =C29-D29
B30: =Instellingen!$F$12 | D30: =SUMIF($I$12:$I$51,B30,$J$12:$J$51) | E30: =C30-D30
B31: =Instellingen!$F$13 | D31: =SUMIF($I$12:$I$51,B31,$J$12:$J$51) | E31: =C31-D31
B32: =Instellingen!$F$14 | D32: =SUMIF($I$12:$I$51,B32,$J$12:$J$51) | E32: =C32-D32
B33: =Instellingen!$F$15 | D33: =SUMIF($I$12:$I$51,B33,$J$12:$J$51) | E33: =C33-D33
B34: =Instellingen!$F$16 | D34: =SUMIF($I$12:$I$51,B34,$J$12:$J$51) | E34: =C34-D34
B35: =Instellingen!$F$17 | D35: =SUMIF($I$12:$I$51,B35,$J$12:$J$51) | E35: =C35-D35
B36: =Instellingen!$F$18 | D36: =SUMIF($I$12:$I$51,B36,$J$12:$J$51) | E36: =C36-D36
B37: =Instellingen!$F$19 | D37: =SUMIF($I$12:$I$51,B37,$J$12:$J$51) | E37: =C37-D37
B38: Subtotaal | C38: =SUM(C27:C37) | D38: =SUM(D27:D37) | E38: =SUM(E27:E37)
B40: D · Sparen | C40: Begroot | D40: Werkelijk | E40: Verschil
B41: =Instellingen!$H$9 | E41: =D41-C41
B42: =Instellingen!$H$10 | E42: =D42-C42
...

Sheet Juli
B1: Plannerij
B2: Juli
B3: =IF(Instellingen!$C$5="","",Instellingen!$C$5)
B4: A · Inkomen | C4: Begroot | D4: Werkelijk | E4: Verschil | G4: Samenvatting | I4: Begroot | J4: Werkelijk
B5: =Instellingen!$B$9 | E5: =D5-C5 | G5: Totaal inkomen | I5: =C9 | J5: =D9
B6: =Instellingen!$B$10 | E6: =D6-C6 | G6: Totaal uitgaven | I6: =C24+C38 | J6: =D24+D38
B7: =Instellingen!$B$11 | E7: =D7-C7 | G7: Gespaard | I7: =C45 | J7: =D45
B8: =Instellingen!$B$12 | E8: =D8-C8 | G8: Over / tekort | I8: =I5-I6-I7 | J8: =J5-J6-J7
B9: Subtotaal | C9: =SUM(C5:C8) | D9: =SUM(D5:D8) | E9: =SUM(E5:E8)
G10: Uitgavenlogboek | I10: Kies een categorie uit de lijst; het bedrag telt automatisch op bij Variabele uitgaven.
B11: B · Vaste lasten | C11: Begroot | D11: Werkelijk | E11: Verschil | G11: Datum | H11: Omschrijving | I11: Categorie | J11: Bedrag
B12: =Instellingen!$D$9 | E12: =C12-D12
B13: =Instellingen!$D$10 | E13: =C13-D13
B14: =Instellingen!$D$11 | E14: =C14-D14
B15: =Instellingen!$D$12 | E15: =C15-D15
B16: =Instellingen!$D$13 | E16: =C16-D16
B17: =Instellingen!$D$14 | E17: =C17-D17
B18: =Instellingen!$D$15 | E18: =C18-D18
B19: =Instellingen!$D$16 | E19: =C19-D19
B20: =Instellingen!$D$17 | E20: =C20-D20
B21: =Instellingen!$D$18 | E21: =C21-D21
B22: =Instellingen!$D$19 | E22: =C22-D22
B23: =Instellingen!$D$20 | E23: =C23-D23
B24: Subtotaal | C24: =SUM(C12:C23) | D24: =SUM(D12:D23) | E24: =SUM(E12:E23)
B26: C · Variabele uitgaven | C26: Begroot | D26: Werkelijk | E26: Verschil
B27: =Instellingen!$F$9 | D27: =SUMIF($I$12:$I$51,B27,$J$12:$J$51) | E27: =C27-D27
B28: =Instellingen!$F$10 | D28: =SUMIF($I$12:$I$51,B28,$J$12:$J$51) | E28: =C28-D28
B29: =Instellingen!$F$11 | D29: =SUMIF($I$12:$I$51,B29,$J$12:$J$51) | E29: =C29-D29
B30: =Instellingen!$F$12 | D30: =SUMIF($I$12:$I$51,B30,$J$12:$J$51) | E30: =C30-D30
B31: =Instellingen!$F$13 | D31: =SUMIF($I$12:$I$51,B31,$J$12:$J$51) | E31: =C31-D31
B32: =Instellingen!$F$14 | D32: =SUMIF($I$12:$I$51,B32,$J$12:$J$51) | E32: =C32-D32
B33: =Instellingen!$F$15 | D33: =SUMIF($I$12:$I$51,B33,$J$12:$J$51) | E33: =C33-D33
B34: =Instellingen!$F$16 | D34: =SUMIF($I$12:$I$51,B34,$J$12:$J$51) | E34: =C34-D34
B35: =Instellingen!$F$17 | D35: =SUMIF($I$12:$I$51,B35,$J$12:$J$51) | E35: =C35-D35
B36: =Instellingen!$F$18 | D36: =SUMIF($I$12:$I$51,B36,$J$12:$J$51) | E36: =C36-D36
B37: =Instellingen!$F$19 | D37: =SUMIF($I$12:$I$51,B37,$J$12:$J$51) | E37: =C37-D37
B38: Subtotaal | C38: =SUM(C27:C37) | D38: =SUM(D27:D37) | E38: =SUM(E27:E37)
B40: D · Sparen | C40: Begroot | D40: Werkelijk | E40: Verschil
B41: =Instellingen!$H$9 | E41: =D41-C41
B42: =Instellingen!$H$10 | E42: =D42-C42
...

Sheet Augustus
B1: Plannerij
B2: Augustus
B3: =IF(Instellingen!$C$5="","",Instellingen!$C$5)
B4: A · Inkomen | C4: Begroot | D4: Werkelijk | E4: Verschil | G4: Samenvatting | I4: Begroot | J4: Werkelijk
B5: =Instellingen!$B$9 | E5: =D5-C5 | G5: Totaal inkomen | I5: =C9 | J5: =D9
B6: =Instellingen!$B$10 | E6: =D6-C6 | G6: Totaal uitgaven | I6: =C24+C38 | J6: =D24+D38
B7: =Instellingen!$B$11 | E7: =D7-C7 | G7: Gespaard | I7: =C45 | J7: =D45
B8: =Instellingen!$B$12 | E8: =D8-C8 | G8: Over / tekort | I8: =I5-I6-I7 | J8: =J5-J6-J7
B9: Subtotaal | C9: =SUM(C5:C8) | D9: =SUM(D5:D8) | E9: =SUM(E5:E8)
G10: Uitgavenlogboek | I10: Kies een categorie uit de lijst; het bedrag telt automatisch op bij Variabele uitgaven.
B11: B · Vaste lasten | C11: Begroot | D11: Werkelijk | E11: Verschil | G11: Datum | H11: Omschrijving | I11: Categorie | J11: Bedrag
B12: =Instellingen!$D$9 | E12: =C12-D12
B13: =Instellingen!$D$10 | E13: =C13-D13
B14: =Instellingen!$D$11 | E14: =C14-D14
B15: =Instellingen!$D$12 | E15: =C15-D15
B16: =Instellingen!$D$13 | E16: =C16-D16
B17: =Instellingen!$D$14 | E17: =C17-D17
B18: =Instellingen!$D$15 | E18: =C18-D18
B19: =Instellingen!$D$16 | E19: =C19-D19
B20: =Instellingen!$D$17 | E20: =C20-D20
B21: =Instellingen!$D$18 | E21: =C21-D21
B22: =Instellingen!$D$19 | E22: =C22-D22
B23: =Instellingen!$D$20 | E23: =C23-D23
B24: Subtotaal | C24: =SUM(C12:C23) | D24: =SUM(D12:D23) | E24: =SUM(E12:E23)
B26: C · Variabele uitgaven | C26: Begroot | D26: Werkelijk | E26: Verschil
B27: =Instellingen!$F$9 | D27: =SUMIF($I$12:$I$51,B27,$J$12:$J$51) | E27: =C27-D27
B28: =Instellingen!$F$10 | D28: =SUMIF($I$12:$I$51,B28,$J$12:$J$51) | E28: =C28-D28
B29: =Instellingen!$F$11 | D29: =SUMIF($I$12:$I$51,B29,$J$12:$J$51) | E29: =C29-D29
B30: =Instellingen!$F$12 | D30: =SUMIF($I$12:$I$51,B30,$J$12:$J$51) | E30: =C30-D30
B31: =Instellingen!$F$13 | D31: =SUMIF($I$12:$I$51,B31,$J$12:$J$51) | E31: =C31-D31
B32: =Instellingen!$F$14 | D32: =SUMIF($I$12:$I$51,B32,$J$12:$J$51) | E32: =C32-D32
B33: =Instellingen!$F$15 | D33: =SUMIF($I$12:$I$51,B33,$J$12:$J$51) | E33: =C33-D33
B34: =Instellingen!$F$16 | D34: =SUMIF($I$12:$I$51,B34,$J$12:$J$51) | E34: =C34-D34
B35: =Instellingen!$F$17 | D35: =SUMIF($I$12:$I$51,B35,$J$12:$J$51) | E35: =C35-D35
B36: =Instellingen!$F$18 | D36: =SUMIF($I$12:$I$51,B36,$J$12:$J$51) | E36: =C36-D36
B37: =Instellingen!$F$19 | D37: =SUMIF($I$12:$I$51,B37,$J$12:$J$51) | E37: =C37-D37
B38: Subtotaal | C38: =SUM(C27:C37) | D38: =SUM(D27:D37) | E38: =SUM(E27:E37)
B40: D · Sparen | C40: Begroot | D40: Werkelijk | E40: Verschil
B41: =Instellingen!$H$9 | E41: =D41-C41
B42: =Instellingen!$H$10 | E42: =D42-C42
...

Sheet September
B1: Plannerij
B2: September
B3: =IF(Instellingen!$C$5="","",Instellingen!$C$5)
B4: A · Inkomen | C4: Begroot | D4: Werkelijk | E4: Verschil | G4: Samenvatting | I4: Begroot | J4: Werkelijk
B5: =Instellingen!$B$9 | E5: =D5-C5 | G5: Totaal inkomen | I5: =C9 | J5: =D9
B6: =Instellingen!$B$10 | E6: =D6-C6 | G6: Totaal uitgaven | I6: =C24+C38 | J6: =D24+D38
B7: =Instellingen!$B$11 | E7: =D7-C7 | G7: Gespaard | I7: =C45 | J7: =D45
B8: =Instellingen!$B$12 | E8: =D8-C8 | G8: Over / tekort | I8: =I5-I6-I7 | J8: =J5-J6-J7
B9: Subtotaal | C9: =SUM(C5:C8) | D9: =SUM(D5:D8) | E9: =SUM(E5:E8)
G10: Uitgavenlogboek | I10: Kies een categorie uit de lijst; het bedrag telt automatisch op bij Variabele uitgaven.
B11: B · Vaste lasten | C11: Begroot | D11: Werkelijk | E11: Verschil | G11: Datum | H11: Omschrijving | I11: Categorie | J11: Bedrag
B12: =Instellingen!$D$9 | E12: =C12-D12
B13: =Instellingen!$D$10 | E13: =C13-D13
B14: =Instellingen!$D$11 | E14: =C14-D14
B15: =Instellingen!$D$12 | E15: =C15-D15
B16: =Instellingen!$D$13 | E16: =C16-D16
B17: =Instellingen!$D$14 | E17: =C17-D17
B18: =Instellingen!$D$15 | E18: =C18-D18
B19: =Instellingen!$D$16 | E19: =C19-D19
B20: =Instellingen!$D$17 | E20: =C20-D20
B21: =Instellingen!$D$18 | E21: =C21-D21
B22: =Instellingen!$D$19 | E22: =C22-D22
B23: =Instellingen!$D$20 | E23: =C23-D23
B24: Subtotaal | C24: =SUM(C12:C23) | D24: =SUM(D12:D23) | E24: =SUM(E12:E23)
B26: C · Variabele uitgaven | C26: Begroot | D26: Werkelijk | E26: Verschil
B27: =Instellingen!$F$9 | D27: =SUMIF($I$12:$I$51,B27,$J$12:$J$51) | E27: =C27-D27
B28: =Instellingen!$F$10 | D28: =SUMIF($I$12:$I$51,B28,$J$12:$J$51) | E28: =C28-D28
B29: =Instellingen!$F$11 | D29: =SUMIF($I$12:$I$51,B29,$J$12:$J$51) | E29: =C29-D29
B30: =Instellingen!$F$12 | D30: =SUMIF($I$12:$I$51,B30,$J$12:$J$51) | E30: =C30-D30
B31: =Instellingen!$F$13 | D31: =SUMIF($I$12:$I$51,B31,$J$12:$J$51) | E31: =C31-D31
B32: =Instellingen!$F$14 | D32: =SUMIF($I$12:$I$51,B32,$J$12:$J$51) | E32: =C32-D32
B33: =Instellingen!$F$15 | D33: =SUMIF($I$12:$I$51,B33,$J$12:$J$51) | E33: =C33-D33
B34: =Instellingen!$F$16 | D34: =SUMIF($I$12:$I$51,B34,$J$12:$J$51) | E34: =C34-D34
B35: =Instellingen!$F$17 | D35: =SUMIF($I$12:$I$51,B35,$J$12:$J$51) | E35: =C35-D35
B36: =Instellingen!$F$18 | D36: =SUMIF($I$12:$I$51,B36,$J$12:$J$51) | E36: =C36-D36
B37: =Instellingen!$F$19 | D37: =SUMIF($I$12:$I$51,B37,$J$12:$J$51) | E37: =C37-D37
B38: Subtotaal | C38: =SUM(C27:C37) | D38: =SUM(D27:D37) | E38: =SUM(E27:E37)
B40: D · Sparen | C40: Begroot | D40: Werkelijk | E40: Verschil
B41: =Instellingen!$H$9 | E41: =D41-C41
B42: =Instellingen!$H$10 | E42: =D42-C42
...

Sheet Oktober
B1: Plannerij
B2: Oktober
B3: =IF(Instellingen!$C$5="","",Instellingen!$C$5)
B4: A · Inkomen | C4: Begroot | D4: Werkelijk | E4: Verschil | G4: Samenvatting | I4: Begroot | J4: Werkelijk
B5: =Instellingen!$B$9 | E5: =D5-C5 | G5: Totaal inkomen | I5: =C9 | J5: =D9
B6: =Instellingen!$B$10 | E6: =D6-C6 | G6: Totaal uitgaven | I6: =C24+C38 | J6: =D24+D38
B7: =Instellingen!$B$11 | E7: =D7-C7 | G7: Gespaard | I7: =C45 | J7: =D45
B8: =Instellingen!$B$12 | E8: =D8-C8 | G8: Over / tekort | I8: =I5-I6-I7 | J8: =J5-J6-J7
B9: Subtotaal | C9: =SUM(C5:C8) | D9: =SUM(D5:D8) | E9: =SUM(E5:E8)
G10: Uitgavenlogboek | I10: Kies een categorie uit de lijst; het bedrag telt automatisch op bij Variabele uitgaven.
B11: B · Vaste lasten | C11: Begroot | D11: Werkelijk | E11: Verschil | G11: Datum | H11: Omschrijving | I11: Categorie | J11: Bedrag
B12: =Instellingen!$D$9 | E12: =C12-D12
B13: =Instellingen!$D$10 | E13: =C13-D13
B14: =Instellingen!$D$11 | E14: =C14-D14
B15: =Instellingen!$D$12 | E15: =C15-D15
B16: =Instellingen!$D$13 | E16: =C16-D16
B17: =Instellingen!$D$14 | E17: =C17-D17
B18: =Instellingen!$D$15 | E18: =C18-D18
B19: =Instellingen!$D$16 | E19: =C19-D19
B20: =Instellingen!$D$17 | E20: =C20-D20
B21: =Instellingen!$D$18 | E21: =C21-D21
B22: =Instellingen!$D$19 | E22: =C22-D22
B23: =Instellingen!$D$20 | E23: =C23-D23
B24: Subtotaal | C24: =SUM(C12:C23) | D24: =SUM(D12:D23) | E24: =SUM(E12:E23)
B26: C · Variabele uitgaven | C26: Begroot | D26: Werkelijk | E26: Verschil
B27: =Instellingen!$F$9 | D27: =SUMIF($I$12:$I$51,B27,$J$12:$J$51) | E27: =C27-D27
B28: =Instellingen!$F$10 | D28: =SUMIF($I$12:$I$51,B28,$J$12:$J$51) | E28: =C28-D28
B29: =Instellingen!$F$11 | D29: =SUMIF($I$12:$I$51,B29,$J$12:$J$51) | E29: =C29-D29
B30: =Instellingen!$F$12 | D30: =SUMIF($I$12:$I$51,B30,$J$12:$J$51) | E30: =C30-D30
B31: =Instellingen!$F$13 | D31: =SUMIF($I$12:$I$51,B31,$J$12:$J$51) | E31: =C31-D31
B32: =Instellingen!$F$14 | D32: =SUMIF($I$12:$I$51,B32,$J$12:$J$51) | E32: =C32-D32
B33: =Instellingen!$F$15 | D33: =SUMIF($I$12:$I$51,B33,$J$12:$J$51) | E33: =C33-D33
B34: =Instellingen!$F$16 | D34: =SUMIF($I$12:$I$51,B34,$J$12:$J$51) | E34: =C34-D34
B35: =Instellingen!$F$17 | D35: =SUMIF($I$12:$I$51,B35,$J$12:$J$51) | E35: =C35-D35
B36: =Instellingen!$F$18 | D36: =SUMIF($I$12:$I$51,B36,$J$12:$J$51) | E36: =C36-D36
B37: =Instellingen!$F$19 | D37: =SUMIF($I$12:$I$51,B37,$J$12:$J$51) | E37: =C37-D37
B38: Subtotaal | C38: =SUM(C27:C37) | D38: =SUM(D27:D37) | E38: =SUM(E27:E37)
B40: D · Sparen | C40: Begroot | D40: Werkelijk | E40: Verschil
B41: =Instellingen!$H$9 | E41: =D41-C41
B42: =Instellingen!$H$10 | E42: =D42-C42
...

Sheet November
B1: Plannerij
B2: November
B3: =IF(Instellingen!$C$5="","",Instellingen!$C$5)
B4: A · Inkomen | C4: Begroot | D4: Werkelijk | E4: Verschil | G4: Samenvatting | I4: Begroot | J4: Werkelijk
B5: =Instellingen!$B$9 | E5: =D5-C5 | G5: Totaal inkomen | I5: =C9 | J5: =D9
B6: =Instellingen!$B$10 | E6: =D6-C6 | G6: Totaal uitgaven | I6: =C24+C38 | J6: =D24+D38
B7: =Instellingen!$B$11 | E7: =D7-C7 | G7: Gespaard | I7: =C45 | J7: =D45
B8: =Instellingen!$B$12 | E8: =D8-C8 | G8: Over / tekort | I8: =I5-I6-I7 | J8: =J5-J6-J7
B9: Subtotaal | C9: =SUM(C5:C8) | D9: =SUM(D5:D8) | E9: =SUM(E5:E8)
G10: Uitgavenlogboek | I10: Kies een categorie uit de lijst; het bedrag telt automatisch op bij Variabele uitgaven.
B11: B · Vaste lasten | C11: Begroot | D11: Werkelijk | E11: Verschil | G11: Datum | H11: Omschrijving | I11: Categorie | J11: Bedrag
B12: =Instellingen!$D$9 | E12: =C12-D12
B13: =Instellingen!$D$10 | E13: =C13-D13
B14: =Instellingen!$D$11 | E14: =C14-D14
B15: =Instellingen!$D$12 | E15: =C15-D15
B16: =Instellingen!$D$13 | E16: =C16-D16
B17: =Instellingen!$D$14 | E17: =C17-D17
B18: =Instellingen!$D$15 | E18: =C18-D18
B19: =Instellingen!$D$16 | E19: =C19-D19
B20: =Instellingen!$D$17 | E20: =C20-D20
B21: =Instellingen!$D$18 | E21: =C21-D21
B22: =Instellingen!$D$19 | E22: =C22-D22
B23: =Instellingen!$D$20 | E23: =C23-D23
B24: Subtotaal | C24: =SUM(C12:C23) | D24: =SUM(D12:D23) | E24: =SUM(E12:E23)
B26: C · Variabele uitgaven | C26: Begroot | D26: Werkelijk | E26: Verschil
B27: =Instellingen!$F$9 | D27: =SUMIF($I$12:$I$51,B27,$J$12:$J$51) | E27: =C27-D27
B28: =Instellingen!$F$10 | D28: =SUMIF($I$12:$I$51,B28,$J$12:$J$51) | E28: =C28-D28
B29: =Instellingen!$F$11 | D29: =SUMIF($I$12:$I$51,B29,$J$12:$J$51) | E29: =C29-D29
B30: =Instellingen!$F$12 | D30: =SUMIF($I$12:$I$51,B30,$J$12:$J$51) | E30: =C30-D30
B31: =Instellingen!$F$13 | D31: =SUMIF($I$12:$I$51,B31,$J$12:$J$51) | E31: =C31-D31
B32: =Instellingen!$F$14 | D32: =SUMIF($I$12:$I$51,B32,$J$12:$J$51) | E32: =C32-D32
B33: =Instellingen!$F$15 | D33: =SUMIF($I$12:$I$51,B33,$J$12:$J$51) | E33: =C33-D33
B34: =Instellingen!$F$16 | D34: =SUMIF($I$12:$I$51,B34,$J$12:$J$51) | E34: =C34-D34
B35: =Instellingen!$F$17 | D35: =SUMIF($I$12:$I$51,B35,$J$12:$J$51) | E35: =C35-D35
B36: =Instellingen!$F$18 | D36: =SUMIF($I$12:$I$51,B36,$J$12:$J$51) | E36: =C36-D36
B37: =Instellingen!$F$19 | D37: =SUMIF($I$12:$I$51,B37,$J$12:$J$51) | E37: =C37-D37
B38: Subtotaal | C38: =SUM(C27:C37) | D38: =SUM(D27:D37) | E38: =SUM(E27:E37)
B40: D · Sparen | C40: Begroot | D40: Werkelijk | E40: Verschil
B41: =Instellingen!$H$9 | E41: =D41-C41
B42: =Instellingen!$H$10 | E42: =D42-C42
...

Sheet December
B1: Plannerij
B2: December
B3: =IF(Instellingen!$C$5="","",Instellingen!$C$5)
B4: A · Inkomen | C4: Begroot | D4: Werkelijk | E4: Verschil | G4: Samenvatting | I4: Begroot | J4: Werkelijk
B5: =Instellingen!$B$9 | E5: =D5-C5 | G5: Totaal inkomen | I5: =C9 | J5: =D9
B6: =Instellingen!$B$10 | E6: =D6-C6 | G6: Totaal uitgaven | I6: =C24+C38 | J6: =D24+D38
B7: =Instellingen!$B$11 | E7: =D7-C7 | G7: Gespaard | I7: =C45 | J7: =D45
B8: =Instellingen!$B$12 | E8: =D8-C8 | G8: Over / tekort | I8: =I5-I6-I7 | J8: =J5-J6-J7
B9: Subtotaal | C9: =SUM(C5:C8) | D9: =SUM(D5:D8) | E9: =SUM(E5:E8)
G10: Uitgavenlogboek | I10: Kies een categorie uit de lijst; het bedrag telt automatisch op bij Variabele uitgaven.
B11: B · Vaste lasten | C11: Begroot | D11: Werkelijk | E11: Verschil | G11: Datum | H11: Omschrijving | I11: Categorie | J11: Bedrag
B12: =Instellingen!$D$9 | E12: =C12-D12
B13: =Instellingen!$D$10 | E13: =C13-D13
B14: =Instellingen!$D$11 | E14: =C14-D14
B15: =Instellingen!$D$12 | E15: =C15-D15
B16: =Instellingen!$D$13 | E16: =C16-D16
B17: =Instellingen!$D$14 | E17: =C17-D17
B18: =Instellingen!$D$15 | E18: =C18-D18
B19: =Instellingen!$D$16 | E19: =C19-D19
B20: =Instellingen!$D$17 | E20: =C20-D20
B21: =Instellingen!$D$18 | E21: =C21-D21
B22: =Instellingen!$D$19 | E22: =C22-D22
B23: =Instellingen!$D$20 | E23: =C23-D23
B24: Subtotaal | C24: =SUM(C12:C23) | D24: =SUM(D12:D23) | E24: =SUM(E12:E23)
B26: C · Variabele uitgaven | C26: Begroot | D26: Werkelijk | E26: Verschil
B27: =Instellingen!$F$9 | D27: =SUMIF($I$12:$I$51,B27,$J$12:$J$51) | E27: =C27-D27
B28: =Instellingen!$F$10 | D28: =SUMIF($I$12:$I$51,B28,$J$12:$J$51) | E28: =C28-D28
B29: =Instellingen!$F$11 | D29: =SUMIF($I$12:$I$51,B29,$J$12:$J$51) | E29: =C29-D29
B30: =Instellingen!$F$12 | D30: =SUMIF($I$12:$I$51,B30,$J$12:$J$51) | E30: =C30-D30
B31: =Instellingen!$F$13 | D31: =SUMIF($I$12:$I$51,B31,$J$12:$J$51) | E31: =C31-D31
B32: =Instellingen!$F$14 | D32: =SUMIF($I$12:$I$51,B32,$J$12:$J$51) | E32: =C32-D32
B33: =Instellingen!$F$15 | D33: =SUMIF($I$12:$I$51,B33,$J$12:$J$51) | E33: =C33-D33
B34: =Instellingen!$F$16 | D34: =SUMIF($I$12:$I$51,B34,$J$12:$J$51) | E34: =C34-D34
B35: =Instellingen!$F$17 | D35: =SUMIF($I$12:$I$51,B35,$J$12:$J$51) | E35: =C35-D35
B36: =Instellingen!$F$18 | D36: =SUMIF($I$12:$I$51,B36,$J$12:$J$51) | E36: =C36-D36
B37: =Instellingen!$F$19 | D37: =SUMIF($I$12:$I$51,B37,$J$12:$J$51) | E37: =C37-D37
B38: Subtotaal | C38: =SUM(C27:C37) | D38: =SUM(D27:D37) | E38: =SUM(E27:E37)
B40: D · Sparen | C40: Begroot | D40: Werkelijk | E40: Verschil
B41: =Instellingen!$H$9 | E41: =D41-C41
B42: =Instellingen!$H$10 | E42: =D42-C42
...

Sheet Spaardoelen
B1: Plannerij
B2: Spaardoelen
B3: Doelbedrag, startbedrag en streefdatum vul je in; de rest rekent automatisch.
B5: Spaardoel | C5: Doelbedrag | D5: Al gespaard vóór dit jaar | E5: Gespaard dit jaar | F5: Totaal gespaard | G5: % behaald | H5: Nog te gaan | I5: Streefdatum | J5: Nodig per maand
B6: =Instellingen!$H$9 | E6: ='Januari'!D41+'Februari'!D41+'Maart'!D41+'April'!D41+'Mei'!D41+'Juni'!D41+'Juli'!D41+'Augustus'!D41+'September'!D41+'Oktober'!D41+'November'!D41+'December'!D41 | F6: =D6+E6 | G6: =IFERROR(MIN(1,F6/C6),0) | H6: =MAX(0,C6-F6) | J6: =IF(I6="",0,IFERROR(ROUND(H6/MAX(1,(YEAR(I6)-YEAR(TODAY()))*12+MONTH(I6)-MONTH(TODAY())),2),0))
B7: =Instellingen!$H$10 | E7: ='Januari'!D42+'Februari'!D42+'Maart'!D42+'April'!D42+'Mei'!D42+'Juni'!D42+'Juli'!D42+'Augustus'!D42+'September'!D42+'Oktober'!D42+'November'!D42+'December'!D42 | F7: =D7+E7 | G7: =IFERROR(MIN(1,F7/C7),0) | H7: =MAX(0,C7-F7) | J7: =IF(I7="",0,IFERROR(ROUND(H7/MAX(1,(YEAR(I7)-YEAR(TODAY()))*12+MONTH(I7)-MONTH(TODAY())),2),0))
B8: =Instellingen!$H$11 | E8: ='Januari'!D43+'Februari'!D43+'Maart'!D43+'April'!D43+'Mei'!D43+'Juni'!D43+'Juli'!D43+'Augustus'!D43+'September'!D43+'Oktober'!D43+'November'!D43+'December'!D43 | F8: =D8+E8 | G8: =IFERROR(MIN(1,F8/C8),0) | H8: =MAX(0,C8-F8) | J8: =IF(I8="",0,IFERROR(ROUND(H8/MAX(1,(YEAR(I8)-YEAR(TODAY()))*12+MONTH(I8)-MONTH(TODAY())),2),0))
B9: =Instellingen!$H$12 | E9: ='Januari'!D44+'Februari'!D44+'Maart'!D44+'April'!D44+'Mei'!D44+'Juni'!D44+'Juli'!D44+'Augustus'!D44+'September'!D44+'Oktober'!D44+'November'!D44+'December'!D44 | F9: =D9+E9 | G9: =IFERROR(MIN(1,F9/C9),0) | H9: =MAX(0,C9-F9) | J9: =IF(I9="",0,IFERROR(ROUND(H9/MAX(1,(YEAR(I9)-YEAR(TODAY()))*12+MONTH(I9)-MONTH(TODAY())),2),0))
B10: Totaal | C10: =SUM(C6:C9) | D10: =SUM(D6:D9) | E10: =SUM(E6:E9) | F10: =SUM(F6:F9) | G10: =IFERROR(MIN(1,F10/C10),0) | H10: =SUM(H6:H9) | J10: =SUM(J6:J9)
B12: Gespaard dit jaar = som van de kolom Werkelijk onder 'D · Sparen' op alle maandtabbladen. Nodig per maand = Nog te gaan ÷ aantal maanden tot de streefdatum.

Sheet Schulden
B1: Plannerij
B2: Schulden
B3: Overzicht van leningen en schulden. Groene cellen invullen; restant en einddatum rekenen automatisch.
B5: Schuld | C5: Schuldeiser | D5: Oorspronkelijk bedrag | E5: Rente % / jaar | F5: Maandbedrag | G5: Al afgelost | H5: Restant | I5: Maanden te gaan | J5: Verwachte einddatum
H6: =MAX(0,D6-G6) | I6: =IF(AND(ISNUMBER(F6),F6>0,H6>0),IFERROR(ROUNDUP(IF(E6=0,H6/F6,NPER(E6/12,-F6,H6)),0),"n.v.t."),"") | J6: =IF(ISNUMBER(I6),DATE(YEAR(TODAY()),MONTH(TODAY())+I6,1),"")
H7: =MAX(0,D7-G7) | I7: =IF(AND(ISNUMBER(F7),F7>0,H7>0),IFERROR(ROUNDUP(IF(E7=0,H7/F7,NPER(E7/12,-F7,H7)),0),"n.v.t."),"") | J7: =IF(ISNUMBER(I7),DATE(YEAR(TODAY()),MONTH(TODAY())+I7,1),"")
H8: =MAX(0,D8-G8) | I8: =IF(AND(ISNUMBER(F8),F8>0,H8>0),IFERROR(ROUNDUP(IF(E8=0,H8/F8,NPER(E8/12,-F8,H8)),0),"n.v.t."),"") | J8: =IF(ISNUMBER(I8),DATE(YEAR(TODAY()),MONTH(TODAY())+I8,1),"")
H9: =MAX(0,D9-G9) | I9: =IF(AND(ISNUMBER(F9),F9>0,H9>0),IFERROR(ROUNDUP(IF(E9=0,H9/F9,NPER(E9/12,-F9,H9)),0),"n.v.t."),"") | J9: =IF(ISNUMBER(I9),DATE(YEAR(TODAY()),MONTH(TODAY())+I9,1),"")
H10: =MAX(0,D10-G10) | I10: =IF(AND(ISNUMBER(F10),F10>0,H10>0),IFERROR(ROUNDUP(IF(E10=0,H10/F10,NPER(E10/12,-F10,H10)),0),"n.v.t."),"") | J10: =IF(ISNUMBER(I10),DATE(YEAR(TODAY()),MONTH(TODAY())+I10,1),"")
H11: =MAX(0,D11-G11) | I11: =IF(AND(ISNUMBER(F11),F11>0,H11>0),IFERROR(ROUNDUP(IF(E11=0,H11/F11,NPER(E11/12,-F11,H11)),0),"n.v.t."),"") | J11: =IF(ISNUMBER(I11),DATE(YEAR(TODAY()),MONTH(TODAY())+I11,1),"")
H12: =MAX(0,D12-G12) | I12: =IF(AND(ISNUMBER(F12),F12>0,H12>0),IFERROR(ROUNDUP(IF(E12=0,H12/F12,NPER(E12/12,-F12,H12)),0),"n.v.t."),"") | J12: =IF(ISNUMBER(I12),DATE(YEAR(TODAY()),MONTH(TODAY())+I12,1),"")
H13: =MAX(0,D13-G13) | I13: =IF(AND(ISNUMBER(F13),F13>0,H13>0),IFERROR(ROUNDUP(IF(E13=0,H13/F13,NPER(E13/12,-F13,H13)),0),"n.v.t."),"") | J13: =IF(ISNUMBER(I13),DATE(YEAR(TODAY()),MONTH(TODAY())+I13,1),"")
B14: Totaal | D14: =SUM(D6:D13) | F14: =SUM(F6:F13) | G14: =SUM(G6:G13) | H14: =SUM(H6:H13)
B16: Sneeuwbal of lawine?
B17: Sneeuwbalmethode: los eerst de kleinste schuld volledig af en gebruik dat vrijgekomen maandbedrag voor de volgende – snelle succeservaringen houden je gemotiveerd.
B18: Lawinemethode: begin bij de schuld met de hoogste rente – wiskundig het goedkoopst, omdat je de minste rente betaalt.
B19: Maanden te gaan is berekend met NPER op basis van rente, maandbedrag en restant. 'n.v.t.' betekent dat het maandbedrag lager is dan de maandelijkse rente.

Sheet Abonnementen
B1: Plannerij
B2: Abonnementen
B3: Checklist van alles wat maandelijks afschrijft. Zet 'Nog nodig?' op Nee en zie wat je bespaart.
B5: Dienst | C5: Prijs per maand | D5: Prijs per jaar | E5: Betaaldag | F5: Opzegtermijn | G5: Nog nodig?
D6: =C6*12
D7: =C7*12
D8: =C8*12
D9: =C9*12
D10: =C10*12
D11: =C11*12
D12: =C12*12
D13: =C13*12
D14: =C14*12
D15: =C15*12
D16: =C16*12
D17: =C17*12
... D25: =C25*12
B26: Totaal | C26: =SUM(C6:C25) | D26: =SUM(D6:D25)
B27: Besparing als je alle 'Nee' opzegt | C27: =SUMIF(G6:G25,"Nee",C6:C25) | D27: =C27*12
B29: Tip: zet de opzegtermijn (bv. '1 maand') erbij en plan de opzegging vóór de volgende betaaldag.

Sheet Spaarpotjes 52 weken
B1: Plannerij
B2: Spaarpotjes 52 weken
B3: De 52-weken spaarchallenge: elke week iets meer opzij. Zet een ✓ als het gelukt is.
B5: Eigen variant – stap per week (€) | F5: 2 | G5: Week 1 = 1× stap, week 52 = 52× stap. Vul een ander bedrag in voor een eigen challenge.
B8: Week | C8: Klassiek (€1 → €52) | D8: Gedaan | F8: Omgekeerd (€52 → €1) | G8: Gedaan | I8: Eigen variant | J8: Gedaan
B9: 1 | C9: =B9 | F9: =53-B9 | I9: =B9*$F$5
B10: 2 | C10: =B10 | F10: =53-B10 | I10: =B10*$F$5
B11: 3 | C11: =B11 | F11: =53-B11 | I11: =B11*$F$5
B12: 4 | C12: =B12 | F12: =53-B12 | I12: =B12*$F$5
B13: 5 | C13: =B13 | F13: =53-B13 | I13: =B13*$F$5
B14: 6 | C14: =B14 | F14: =53-B14 | I14: =B14*$F$5
B15: 7 | C15: =B15 | F15: =53-B15 | I15: =B15*$F$5
B16: 8 | C16: =B16 | F16: =53-B16 | I16: =B16*$F$5
B17: 9 | C17: =B17 | F17: =53-B17 | I17: =B17*$F$5
B18: 10 | C18: =B18 | F18: =53-B18 | I18: =B18*$F$5
B19: 11 | C19: =B19 | F19: =53-B19 | I19: =B19*$F$5
B20: 12 | C20: =B20 | F20: =53-B20 | I20: =B20*$F$5
... B60: 52 | C60: =B60 | F60: =53-B60 | I60: =B60*$F$5
B61: Totaal | C61: =SUM(C9:C60) | F61: =SUM(F9:F60) | I61: =SUM(I9:I60)
B62: Al gespaard | C62: =SUMIF(D9:D60,"✓",C9:C60) | F62: =SUMIF(G9:G60,"✓",F9:F60) | I62: =SUMIF(J9:J60,"✓",I9:I60)
B64: Klassiek en omgekeerd leveren allebei € 1.378,00 op na 52 weken. Omgekeerd is fijn als je in december liever weinig hoeft te missen.
